Workbook

Sheet Sheet1
B1: 2-yr Tsy | C1: 10-yr Tsy | D1: CHG in bp (2-yr Tsy) | E1: CHG in bp (10-yr Tsy)
A2: 45566 | B2: 3.606 | C2: 3.732
A3: 45567 | B3: 3.643 | C3: 3.783 | D3: =100*(B3-B2) -> 3.7 | E3: =100*(C3-C2) -> 5.1
A4: 45568 | B4: 3.706 | C4: 3.847 | D4: =100*(B4-B3) -> 6.3 | E4: =100*(C4-C3) -> 6.4
A5: 45569 | B5: 3.924 | C5: 3.968 | D5: =100*(B5-B4) -> 21.8 | E5: =100*(C5-C4) -> 12.1
A6: 45572 | B6: 3.996 | C6: 4.027 | D6: =100*(B6-B5) -> 7.2 | E6: =100*(C6-C5) -> 5.9
A7: 45573 | B7: 3.959 | C7: 4.013 | D7: =100*(B7-B6) -> -3.7 | E7: =100*(C7-C6) -> -1.4
A8: 45574 | B8: 4.024 | C8: 4.074 | D8: =100*(B8-B7) -> 6.5 | E8: =100*(C8-C7) -> 6.1
A9: 45575 | B9: 3.959 | C9: 4.063 | D9: =100*(B9-B8) -> -6.5 | E9: =100*(C9-C8) -> -1.1
A10: 45576 | B10: 3.957 | C10: 4.101 | D10: =100*(B10-B9) -> -0.2 | E10: =100*(C10-C9) -> 3.8
A11: 45579 | B11: 3.957 | C11: 4.101 | D11: =100*(B11-B10) -> 0 | E11: =100*(C11-C10) -> 0
A12: 45580 | B12: 3.948 | C12: 4.034 | D12: =100*(B12-B11) -> -0.9 | E12: =100*(C12-C11) -> -6.7
A13: 45581 | B13: 3.94 | C13: 4.014 | D13: =100*(B13-B12) -> -0.8 | E13: =100*(C13-C12) -> -2
A14: 45582 | B14: 3.973 | C14: 4.092 | D14: =100*(B14-B13) -> 3.3 | E14: =100*(C14-C13) -> 7.8
... A16: 45586 | B16: 4.033 | C16: 4.197 | D16: =100*(B16-B15) -> 8.4 | E16: =100*(C16-C15) -> 11.3
A17: 45587 | B17: 4.033 | C17: 4.209 | D17: =100*(B17-B16) -> 0 | E17: =100*(C17-C16) -> 1.2 | H17: 2-yr Tsy
A18: 45588 | B18: 4.08 | C18: 4.247 | D18: =100*(B18-B17) -> 4.7 | E18: =100*(C18-C17) -> 3.8 | H18: ="-dP/dY = PV01" -> -dP/dY = PV01 | I18: =1.878 -> 1.878
A19: 45589 | B19: 4.081 | C19: 4.213 | D19: =100*(B19-B18) -> 0.1 | E19: =100*(C19-C18) -> -3.4 | H19: d2P/dY2 | I19: =(0.045*99.7513)/100 -> 0.044888085
A20: 45590 | B20: 4.107 | C20: 4.241 | D20: =100*(B20-B19) -> 2.6 | E20: =100*(C20-C19) -> 2.8
A21: 45593 | B21: 4.141 | C21: 4.283 | D21: =100*(B21-B20) -> 3.4 | E21: =100*(C21-C20) -> 4.2
A22: 45594 | B22: 4.098 | C22: 4.255 | D22: =100*(B22-B21) -> -4.3 | E22: =100*(C22-C21) -> -2.8
A23: 45595 | B23: 4.184 | C23: 4.301 | D23: =100*(B23-B22) -> 8.6 | E23: =100*(C23-C22) -> 4.6
A24: 45596 | B24: 4.172 | C24: 4.285 | D24: =100*(B24-B23) -> -1.2 | E24: =100*(C24-C23) -> -1.6
A25: 45597 | B25: 4.209 | C25: 4.385 | D25: =100*(B25-B24) -> 3.7 | E25: =100*(C25-C24) -> 10
A26: 45600 | B26: 4.162 | C26: 4.286 | D26: =100*(B26-B25) -> -4.7 | E26: =100*(C26-C25) -> -9.9
A27: 45601 | B27: 4.18 | C27: 4.273 | D27: =100*(B27-B26) -> 1.8 | E27: =100*(C27-C26) -> -1.3
A28: 45602 | B28: 4.264 | C28: 4.433 | D28: =100*(B28-B27) -> 8.4 | E28: =100*(C28-C27) -> 16
A29: 45603 | B29: 4.2 | C29: 4.328 | D29: =100*(B29-B28) -> -6.4 | E29: =100*(C29-C28) -> -10.5
A30: 45604 | B30: 4.255 | C30: 4.305 | D30: =100*(B30-B29) -> 5.5 | E30: =100*(C30-C29) -> -2.3
A31: 45607 | B31: 4.255 | C31: 4.305 | D31: =100*(B31-B30) -> 0 | E31: =100*(C31-C30) -> 0
... A40: 45618 | B40: 4.376 | C40: 4.401 | D40: =100*(B40-B39) -> 2.6 | E40: =100*(C40-C39) -> -2.2
A41: 45621 | B41: 4.272 | C41: 4.275 | D41: =100*(B41-B40) -> -10.4 | E41: =100*(C41-C40) -> -12.6 | I41: 10-yr Tsy
A42: 45622 | B42: 4.257 | C42: 4.307 | D42: =100*(B42-B41) -> -1.5 | E42: =100*(C42-C41) -> 3.2 | I42: ="-dP/dY = PV01" -> -dP/dY = PV01 | J42: 7.382
A43: 45623 | B43: 4.229 | C43: 4.264 | D43: =100*(B43-B42) -> -2.8 | E43: =100*(C43-C42) -> -4.3 | I43: d2P/dY2 | J43: =0.723*95.5438/100 -> 0.69078167
A44: 45624 | B44: 4.229 | C44: 4.264 | D44: =100*(B44-B43) -> 0 | E44: =100*(C44-C43) -> 0
A45: 45625 | B45: 4.153 | C45: 4.17 | D45: =100*(B45-B44) -> -7.6 | E45: =100*(C45-C44) -> -9.4
A46: 45628 | B46: 4.182 | C46: 4.192 | D46: =100*(B46-B45) -> 2.9 | E46: =100*(C46-C45) -> 2.2
A47: 45629 | B47: 4.181 | C47: 4.225 | D47: =100*(B47-B46) -> -0.1 | E47: =100*(C47-C46) -> 3.3
A48: 45630 | B48: 4.128 | C48: 4.181 | D48: =100*(B48-B47) -> -5.3 | E48: =100*(C48-C47) -> -4.4
A49: 45631 | B49: 4.145 | C49: 4.177 | D49: =100*(B49-B48) -> 1.7 | E49: =100*(C49-C48) -> -0.4
...

Sheet Summary
A1: FRE-GY 6123 Financial Risk Management, Fall 2026: Homework 1
A2: Name | B2: Rajvardhan Pawar
A3: NetID | B3: rsp9234
A5: Question | B5: Result | C5: Value | D5: Units | E5: Worked on sheet
A6: Q1 | B6: 2-yr shocks: % of days within 1 SD of the mean | C6: ='Q1-Q4 Stats'!B14 -> 0.73896353 | D6: % of days | E6: Q1-Q4 Stats
A7: Q1 | B7: 2-yr shocks: % of days within 2 SD of the mean | C7: ='Q1-Q4 Stats'!B18 -> 0.95201536 | D7: % of days | E7: Q1-Q4 Stats
A8: Q1 | B8: 10-yr shocks: % of days within 1 SD of the mean | C8: ='Q1-Q4 Stats'!C14 -> 0.72744722 | D8: % of days | E8: Q1-Q4 Stats
A9: Q1 | B9: 10-yr shocks: % of days within 2 SD of the mean | C9: ='Q1-Q4 Stats'!C18 -> 0.94241843 | D9: % of days | E9: Q1-Q4 Stats
A10: Q2 | B10: Sample correlation, full 2-year window | C10: ='Q1-Q4 Stats'!B23 -> 0.8204378 | D10: no units | E10: Q1-Q4 Stats
A11: Q3 | B11: E[2-yr shock | 10-yr shock >= 0] | C11: ='Q1-Q4 Stats'!B27 -> 2.9409091 | D11: bp | E11: Q1-Q4 Stats
A12: Q3 | B12: E[10-yr shock | 2-yr shock >= 0] | C12: ='Q1-Q4 Stats'!B28 -> 3.2185455 | D12: bp | E12: Q1-Q4 Stats
A13: Q4 | B13: Days with both shocks more than 1 SD from the mean | C13: ='Q1-Q4 Stats'!B38 -> 96 | D13: days | E13: Q1-Q4 Stats
A14: Q4 | B14: Correlation on those days | C14: ='Q1-Q4 Stats'!B39 -> 0.94590478 | D14: no units | E14: Q1-Q4 Stats
A15: Q5 | B15: 2-yr notes to sell against long $20 million 10-yr | C15: ='Q5-Q7 VaR'!B11 -> 78.615548 | D15: $ million face | E15: Q5-Q7 VaR
A16: Q6 | B16: 10-yr notes with the same PV01 as $15 million 2-yr | C16: ='Q5-Q7 VaR'!B19 -> 3.816039 | D16: $ million face | E16: Q5-Q7 VaR
A17: Q7 | B17: 99% 1-day VaR of the Q6 portfolio | C17: ='Q5-Q7 VaR'!B34 -> 66844.07 | D17: $ | E17: Q5-Q7 VaR
A18: Q8 | B18: A with the lowest 99% 1-day VaR | C18: ='Q8 VaR Graph'!B5 -> -2.75 | D18: $ million face | E18: Q8 VaR Graph
A19: Q8 | B19: VaR at that A | C19: ='Q8 VaR Graph'!C5 -> 19532.975 | D19: $ | E19: Q8 VaR Graph
A20: Q8 | B20: A with zero total PV01 | C20: ='Q8 VaR Graph'!B6 -> -3.816039 | D20: $ million face | E20: Q8 VaR Graph
A21: Q8 | B21: VaR at zero total PV01 | C21: ='Q8 VaR Graph'!C6 -> 20106.049 | D21: $ | E21: Q8 VaR Graph
A23: Assumptions and VaR method
A24: 1. Shocks are the daily yield changes in bp on Sheet1: 521 changes from 522 daily yields, 1-Oct-24 to 30-Sep-26. Days with a zero change are kept.
A25: 2. Mean and standard deviation are sample statistics over the full window (STDEV.S, n-1). 'Within k SD' means |change - mean| <= k x SD.
A26: 3. PV01 and d2P/dY2 come from the Bloomberg screens on Sheet1 (per 100 face) and are held fixed. Position sizes are face amounts.
A27: 4. Repricing (second order, as % of par): price chg = -PV01 x chg/100 + 0.5 x d2P/dY2 x chg^2/10000, with chg in bp. PV01 is a positive number, so a long position loses when the yield rises.
A28: 5. VaR method: historical simulation. Each of the 521 historical (2-yr, 10-yr) change pairs is applied to today's position as an absolute move in bp, each leg is repriced with the formula above and the two legs are added.
A29: 6. 99% 1-day VaR = -(1st percentile of the 521 simulated P&Ls), using PERCENTILE.INC, shown as a positive dollar loss. The 5th, 6th and 7th worst days are also shown on the Q5-Q7 VaR sheet.
A30: 7. One-day horizon, every day in the window weighted equally, and no carry, roll-down or financing cost.

Sheet Q1-Q4 Stats
A1: Q1 to Q4: statistics on the daily yield shocks
A2: Shocks = daily yield changes in bp from Sheet1 (columns D and E), 2-Oct-24 to 30-Sep-26.
G3: Daily working for Q4
A4: Summary statistics | B4: 2-yr Tsy | C4: 10-yr Tsy | D4: Units | G4: Date | H4: 2-yr chg (bp) | I4: 10-yr chg (bp) | J4: 2-yr: more than 1 SD from mean? (1 = yes) | K4: 10-yr: more than 1 SD from mean? (1 = yes) | L4: Both? (Q4 subset) | M4: 2-yr chg on subset days (bp) | N4: 10-yr chg on subset days (bp)
A5: Number of daily changes | B5: =COUNT(Sheet1!$D$3:$D$523) -> 521 | C5: =COUNT(Sheet1!$E$3:$E$523) -> 521 | D5: days | G5: =Sheet1!A3 -> 45567 | H5: =Sheet1!D3 -> 3.7 | I5: =Sheet1!E3 -> 5.1 | J5: =IF(ABS(H5-$B$6)>$B$7,1,0) -> 0 | K5: =IF(ABS(I5-$C$6)>$C$7,1,0) -> 0 | L5: =J5*K5 -> 0 | M5: =IF(L5=1,H5,"") | N5: =IF(L5=1,I5,"")
A6: Mean change | B6: =AVERAGE(Sheet1!$D$3:$D$523) -> 0.2462572 | C6: =AVERAGE(Sheet1!$E$3:$E$523) -> 0.29846449 | D6: bp | G6: =Sheet1!A4 -> 45568 | H6: =Sheet1!D4 -> 6.3 | I6: =Sheet1!E4 -> 6.4 | J6: =IF(ABS(H6-$B$6)>$B$7,1,0) -> 1 | K6: =IF(ABS(I6-$C$6)>$C$7,1,0) -> 1 | L6: =J6*K6 -> 1 | M6: =IF(L6=1,H6,"") -> 6.3 | N6: =IF(L6=1,I6,"") -> 6.4
A7: Standard deviation (sample, n-1) | B7: =_xlfn.STDEV.S(Sheet1!$D$3:$D$523) -> 4.8802576 | C7: =_xlfn.STDEV.S(Sheet1!$E$3:$E$523) -> 4.8538523 | D7: bp | G7: =Sheet1!A5 -> 45569 | H7: =Sheet1!D5 -> 21.8 | I7: =Sheet1!E5 -> 12.1 | J7: =IF(ABS(H7-$B$6)>$B$7,1,0) -> 1 | K7: =IF(ABS(I7-$C$6)>$C$7,1,0) -> 1 | L7: =J7*K7 -> 1 | M7: =IF(L7=1,H7,"") -> 21.8 | N7: =IF(L7=1,I7,"") -> 12.1
A8: Excess kurtosis (0 for a normal) | B8: =KURT(Sheet1!$D$3:$D$523) -> 2.8837219 | C8: =KURT(Sheet1!$E$3:$E$523) -> 0.67159117 | D8: no units | G8: =Sheet1!A6 -> 45572 | H8: =Sheet1!D6 -> 7.2 | I8: =Sheet1!E6 -> 5.9 | J8: =IF(ABS(H8-$B$6)>$B$7,1,0) -> 1 | K8: =IF(ABS(I8-$C$6)>$C$7,1,0) -> 1 | L8: =J8*K8 -> 1 | M8: =IF(L8=1,H8,"") -> 7.2 | N8: =IF(L8=1,I8,"") -> 5.9
G9: =Sheet1!A7 -> 45573 | H9: =Sheet1!D7 -> -3.7 | I9: =Sheet1!E7 -> -1.4 | J9: =IF(ABS(H9-$B$6)>$B$7,1,0) -> 0 | K9: =IF(ABS(I9-$C$6)>$C$7,1,0) -> 0 | L9: =J9*K9 -> 0 | M9: =IF(L9=1,H9,"") | N9: =IF(L9=1,I9,"")
A10: Q1. Share of daily changes within 1 and 2 SD of the mean | B10: 2-yr Tsy | C10: 10-yr Tsy | D10: Units | G10: =Sheet1!A8 -> 45574 | H10: =Sheet1!D8 -> 6.5 | I10: =Sheet1!E8 -> 6.1 | J10: =IF(ABS(H10-$B$6)>$B$7,1,0) -> 1 | K10: =IF(ABS(I10-$C$6)>$C$7,1,0) -> 1 | L10: =J10*K10 -> 1 | M10: =IF(L10=1,H10,"") -> 6.5 | N10: =IF(L10=1,I10,"") -> 6.1
A11: Lower bound: mean - 1 SD | B11: =B6-B7 -> -4.6340004 | C11: =C6-C7 -> -4.5553878 | D11: bp | G11: =Sheet1!A9 -> 45575 | H11: =Sheet1!D9 -> -6.5 | I11: =Sheet1!E9 -> -1.1 | J11: =IF(ABS(H11-$B$6)>$B$7,1,0) -> 1 | K11: =IF(ABS(I11-$C$6)>$C$7,1,0) -> 0 | L11: =J11*K11 -> 0 | M11: =IF(L11=1,H11,"") | N11: =IF(L11=1,I11,"")
A12: Upper bound: mean + 1 SD | B12: =B6+B7 -> 5.1265148 | C12: =C6+C7 -> 5.1523168 | D12: bp | G12: =Sheet1!A10 -> 45576 | H12: =Sheet1!D10 -> -0.2 | I12: =Sheet1!E10 -> 3.8 | J12: =IF(ABS(H12-$B$6)>$B$7,1,0) -> 0 | K12: =IF(ABS(I12-$C$6)>$C$7,1,0) -> 0 | L12: =J12*K12 -> 0 | M12: =IF(L12=1,H12,"") | N12: =IF(L12=1,I12,"")
A13: Days within 1 SD | B13: =COUNTIFS(Sheet1!$D$3:$D$523,">="&B11,Sheet1!$D$3:$D$523,"<="&B12) -> 385 | C13: =COUNTIFS(Sheet1!$E$3:$E$523,">="&C11,Sheet1!$E$3:$E$523,"<="&C12) -> 379 | D13: days | G13: =Sheet1!A11 -> 45579 | H13: =Sheet1!D11 -> 0 | I13: =Sheet1!E11 -> 0 | J13: =IF(ABS(H13-$B$6)>$B$7,1,0) -> 0 | K13: =IF(ABS(I13-$C$6)>$C$7,1,0) -> 0 | L13: =J13*K13 -> 0 | M13: =IF(L13=1,H13,"") | N13: =IF(L13=1,I13,"")
A14: % of days within 1 SD | B14: =B13/B5 -> 0.73896353 | C14: =C13/C5 -> 0.72744722 | D14: % of days | G14: =Sheet1!A12 -> 45580 | H14: =Sheet1!D12 -> -0.9 | I14: =Sheet1!E12 -> -6.7 | J14: =IF(ABS(H14-$B$6)>$B$7,1,0) -> 0 | K14: =IF(ABS(I14-$C$6)>$C$7,1,0) -> 1 | L14: =J14*K14 -> 0 | M14: =IF(L14=1,H14,"") | N14: =IF(L14=1,I14,"")
A15: Lower bound: mean - 2 SD | B15: =B6-2*B7 -> -9.5142579 | C15: =C6-2*C7 -> -9.4092401 | D15: bp | G15: =Sheet1!A13 -> 45581 | H15: =Sheet1!D13 -> -0.8 | I15: =Sheet1!E13 -> -2 | J15: =IF(ABS(H15-$B$6)>$B$7,1,0) -> 0 | K15: =IF(ABS(I15-$C$6)>$C$7,1,0) -> 0 | L15: =J15*K15 -> 0 | M15: =IF(L15=1,H15,"") | N15: =IF(L15=1,I15,"")
A16: Upper bound: mean + 2 SD | B16: =B6+2*B7 -> 10.006772 | C16: =C6+2*C7 -> 10.006169 | D16: bp | G16: =Sheet1!A14 -> 45582 | H16: =Sheet1!D14 -> 3.3 | I16: =Sheet1!E14 -> 7.8 | J16: =IF(ABS(H16-$B$6)>$B$7,1,0) -> 0 | K16: =IF(ABS(I16-$C$6)>$C$7,1,0) -> 1 | L16: =J16*K16 -> 0 | M16: =IF(L16=1,H16,"") | N16: =IF(L16=1,I16,"")
A17: Days within 2 SD | B17: =COUNTIFS(Sheet1!$D$3:$D$523,">="&B15,Sheet1!$D$3:$D$523,"<="&B16) -> 496 | C17: =COUNTIFS(Sheet1!$E$3:$E$523,">="&C15,Sheet1!$E$3:$E$523,"<="&C16) -> 491 | D17: days | G17: =Sheet1!A15 -> 45583 | H17: =Sheet1!D15 -> -2.4 | I17: =Sheet1!E15 -> -0.8 | J17: =IF(ABS(H17-$B$6)>$B$7,1,0) -> 0 | K17: =IF(ABS(I17-$C$6)>$C$7,1,0) -> 0 | L17: =J17*K17 -> 0 | M17: =IF(L17=1,H17,"") | N17: =IF(L17=1,I17,"")
A18: % of days within 2 SD | B18: =B17/B5 -> 0.95201536 | C18: =C17/C5 -> 0.94241843 | D18: % of days | G18: =Sheet1!A16 -> 45586 | H18: =Sheet1!D16 -> 8.4 | I18: =Sheet1!E16 -> 11.3 | J18: =IF(ABS(H18-$B$6)>$B$7,1,0) -> 1 | K18: =IF(ABS(I18-$C$6)>$C$7,1,0) -> 1 | L18: =J18*K18 -> 1 | M18: =IF(L18=1,H18,"") -> 8.4 | N18: =IF(L18=1,I18,"") -> 11.3
A19: For comparison, normal distribution: within 1 SD | B19: =2*_xlfn.NORM.S.DIST(1,TRUE)-1 -> 0.68268949 | C19: =2*_xlfn.NORM.S.DIST(1,TRUE)-1 -> 0.68268949 | D19: % of days | G19: =Sheet1!A17 -> 45587 | H19: =Sheet1!D17 -> 0 | I19: =Sheet1!E17 -> 1.2 | J19: =IF(ABS(H19-$B$6)>$B$7,1,0) -> 0 | K19: =IF(ABS(I19-$C$6)>$C$7,1,0) -> 0 | L19: =J19*K19 -> 0 | M19: =IF(L19=1,H19,"") | N19: =IF(L19=1,I19,"")
A20: For comparison, normal distribution: within 2 SD | B20: =2*_xlfn.NORM.S.DIST(2,TRUE)-1 -> 0.95449974 | C20: =2*_xlfn.NORM.S.DIST(2,TRUE)-1 -> 0.95449974 | D20: % of days | G20: =Sheet1!A18 -> 45588 | H20: =Sheet1!D18 -> 4.7 | I20: =Sheet1!E18 -> 3.8 | J20: =IF(ABS(H20-$B$6)>$B$7,1,0) -> 0 | K20: =IF(ABS(I20-$C$6)>$C$7,1,0) -> 0 | L20: =J20*K20 -> 0 | M20: =IF(L20=1,H20,"") | N20: =IF(L20=1,I20,"")
G21: =Sheet1!A19 -> 45589 | H21: =Sheet1!D19 -> 0.1 | I21: =Sheet1!E19 -> -3.4 | J21: =IF(ABS(H21-$B$6)>$B$7,1,0) -> 0 | K21: =IF(ABS(I21-$C$6)>$C$7,1,0) -> 0 | L21: =J21*K21 -> 0 | M21: =IF(L21=1,H21,"") | N21: =IF(L21=1,I21,"")
A22: Q2. Sample correlation over the full 2-year window | B22: Value | D22: Units | G22: =Sheet1!A20 -> 45590 | H22: =Sheet1!D20 -> 2.6 | I22: =Sheet1!E20 -> 2.8 | J22: =IF(ABS(H22-$B$6)>$B$7,1,0) -> 0 | K22: =IF(ABS(I22-$C$6)>$C$7,1,0) -> 0 | L22: =J22*K22 -> 0 | M22: =IF(L22=1,H22,"") | N22: =IF(L22=1,I22,"")
A23: Correlation of 2-yr and 10-yr daily changes | B23: =CORREL(Sheet1!$D$3:$D$523,Sheet1!$E$3:$E$523) -> 0.8204378 | D23: no units | G23: =Sheet1!A21 -> 45593 | H23: =Sheet1!D21 -> 3.4 | I23: =Sheet1!E21 -> 4.2 | J23: =IF(ABS(H23-$B$6)>$B$7,1,0) -> 0 | K23: =IF(ABS(I23-$C$6)>$C$7,1,0) -> 0 | L23: =J23*K23 -> 0 | M23: =IF(L23=1,H23,"") | N23: =IF(L23=1,I23,"")
G24: =Sheet1!A22 -> 45594 | H24: =Sheet1!D22 -> -4.3 | I24: =Sheet1!E22 -> -2.8 | J24: =IF(ABS(H24-$B$6)>$B$7,1,0) -> 0 | K24: =IF(ABS(I24-$C$6)>$C$7,1,0) -> 0 | L24: =J24*K24 -> 0 | M24: =IF(L24=1,H24,"") | N24: =IF(L24=1,I24,"")
G25: =Sheet1!A23 -> 45595 | H25: =Sheet1!D23 -> 8.6 | I25: =Sheet1!E23 -> 4.6 | J25: =IF(ABS(H25-$B$6)>$B$7,1,0) -> 1 | K25: =IF(ABS(I25-$C$6)>$C$7,1,0) -> 0 | L25: =J25*K25 -> 0 | M25: =IF(L25=1,H25,"") | N25: =IF(L25=1,I25,"")
A26: Q3. Conditional expected values | B26: Value | C26: No. of days | D26: Units | G26: =Sheet1!A24 -> 45596 | H26: =Sheet1!D24 -> -1.2 | I26: =Sheet1!E24 -> -1.6 | J26: =IF(ABS(H26-$B$6)>$B$7,1,0) -> 0 | K26: =IF(ABS(I26-$C$6)>$C$7,1,0) -> 0 | L26: =J26*K26 -> 0 | M26: =IF(L26=1,H26,"") | N26: =IF(L26=1,I26,"")
A27: E[2-yr shock | 10-yr shock >= 0] | B27: =AVERAGEIF(Sheet1!$E$3:$E$523,">=0",Sheet1!$D$3:$D$523) -> 2.9409091 | C27: =COUNTIF(Sheet1!$E$3:$E$523,">=0") -> 286 | D27: bp | G27: =Sheet1!A25 -> 45597 | H27: =Sheet1!D25 -> 3.7 | I27: =Sheet1!E25 -> 10 | J27: =IF(ABS(H27-$B$6)>$B$7,1,0) -> 0 | K27: =IF(ABS(I27-$C$6)>$C$7,1,0) -> 1 | L27: =J27*K27 -> 0 | M27: =IF(L27=1,H27,"") | N27: =IF(L27=1,I27,"")
A28: E[10-yr shock | 2-yr shock >= 0] | B28: =AVERAGEIF(Sheet1!$D$3:$D$523,">=0",Sheet1!$E$3:$E$523) -> 3.2185455 | C28: =COUNTIF(Sheet1!$D$3:$D$523,">=0") -> 275 | D28: bp | G28: =Sheet1!A26 -> 45600 | H28: =Sheet1!D26 -> -4.7 | I28: =Sheet1!E26 -> -9.9 | J28: =IF(ABS(H28-$B$6)>$B$7,1,0) -> 1 | K28: =IF(ABS(I28-$C$6)>$C$7,1,0) -> 1 | L28: =J28*K28 -> 1 | M28: =IF(L28=1,H28,"") -> -4.7 | N28: =IF(L28=1,I28,"") -> -9.9
A29: E[2-yr shock | 10-yr shock < 0] | B29: =AVERAGEIF(Sheet1!$E$3:$E$523,"<0",Sheet1!$D$3:$D$523) -> -3.0331915 | C29: =COUNTIF(Sheet1!$E$3:$E$523,"<0") -> 235 | D29: bp | G29: =Sheet1!A27 -> 45601 | H29: =Sheet1!D27 -> 1.8 | I29: =Sheet1!E27 -> -1.3 | J29: =IF(ABS(H29-$B$6)>$B$7,1,0) -> 0 | K29: =IF(ABS(I29-$C$6)>$C$7,1,0) -> 0 | L29: =J29*K29 -> 0 | M29: =IF(L29=1,H29,"") | N29: =IF(L29=1,I29,"")
A30: E[10-yr shock | 2-yr shock < 0] | B30: =AVERAGEIF(Sheet1!$D$3:$D$523,"<0",Sheet1!$E$3:$E$523) -> -2.9658537 | C30: =COUNTIF(Sheet1!$D$3:$D$523,"<0") -> 246 | D30: bp | G30: =Sheet1!A28 -> 45602 | H30: =Sheet1!D28 -> 8.4 | I30: =Sheet1!E28 -> 16 | J30: =IF(ABS(H30-$B$6)>$B$7,1,0) -> 1 | K30: =IF(ABS(I30-$C$6)>$C$7,1,0) -> 1 | L30: =J30*K30 -> 1 | M30: =IF(L30=1,H30,"") -> 8.4 | N30: =IF(L30=1,I30,"") -> 16
A31: Rough implied correlation from E[2-yr | 10-yr >= 0] | B31: =B27/(B7*SQRT(2/PI())) -> 0.75526402 | D31: no units | G31: =Sheet1!A29 -> 45603 | H31: =Sheet1!D29 -> -6.4 | I31: =Sheet1!E29 -> -10.5 | J31: =IF(ABS(H31-$B$6)>$B$7,1,0) -> 1 | K31: =IF(ABS(I31-$C$6)>$C$7,1,0) -> 1 | L31: =J31*K31 -> 1 | M31: =IF(L31=1,H31,"") -> -6.4 | N31: =IF(L31=1,I31,"") -> -10.5
A32: Rough implied correlation from E[10-yr | 2-yr >= 0] | B32: =B28/(C7*SQRT(2/PI())) -> 0.83106124 | D32: no units | G32: =Sheet1!A30 -> 45604 | H32: =Sheet1!D30 -> 5.5 | I32: =Sheet1!E30 -> -2.3 | J32: =IF(ABS(H32-$B$6)>$B$7,1,0) -> 1 | K32: =IF(ABS(I32-$C$6)>$C$7,1,0) -> 0 | L32: =J32*K32 -> 0 | M32: =IF(L32=1,H32,"") | N32: =IF(L32=1,I32,"")
A33: Implied correlation uses E[X | Y>=0] = corr x SD(X) x sqrt(2/pi), which holds for joint normal shocks with zero mean. | G33: =Sheet1!A31 -> 45607 | H33: =Sheet1!D31 -> 0 | I33: =Sheet1!E31 -> 0 | J33: =IF(ABS(H33-$B$6)>$B$7,1,0) -> 0 | K33: =IF(ABS(I33-$C$6)>$C$7,1,0) -> 0 | L33: =J33*K33 -> 0 | M33: =IF(L33=1,H33,"") | N33: =IF(L33=1,I33,"")
G34: =Sheet1!A32 -> 45608 | H34: =Sheet1!D32 -> 8.7 | I34: =Sheet1!E32 -> 12.4 | J34: =IF(ABS(H34-$B$6)>$B$7,1,0) -> 1 | K34: =IF(ABS(I34-$C$6)>$C$7,1,0) -> 1 | L34: =J34*K34 -> 1 | M34: =IF(L34=1,H34,"") -> 8.7 | N34: =IF(L34=1,I34,"") -> 12.4
A35: Q4. Days when BOTH shocks are more than 1 SD from their mean | B35: Value | D35: Units | G35: =Sheet1!A33 -> 45609 | H35: =Sheet1!D33 -> -5.4 | I35: =Sheet1!E33 -> 2.3 | J35: =IF(ABS(H35-$B$6)>$B$7,1,0) -> 1 | K35: =IF(ABS(I35-$C$6)>$C$7,1,0) -> 0 | L35: =J35*K35 -> 0 | M35: =IF(L35=1,H35,"") | N35: =IF(L35=1,I35,"")
A36: 2-yr: days more than 1 SD from the mean | B36: =SUM(J5:J525) -> 136 | D36: days | G36: =Sheet1!A34 -> 45610 | H36: =Sheet1!D34 -> 5.9 | I36: =Sheet1!E34 -> -1.5 | J36: =IF(ABS(H36-$B$6)>$B$7,1,0) -> 1 | K36: =IF(ABS(I36-$C$6)>$C$7,1,0) -> 0 | L36: =J36*K36 -> 0 | M36: =IF(L36=1,H36,"") | N36: =IF(L36=1,I36,"")
A37: 10-yr: days more than 1 SD from the mean | B37: =SUM(K5:K525) -> 142 | D37: days | G37: =Sheet1!A35 -> 45611 | H37: =Sheet1!D35 -> -4.2 | I37: =Sheet1!E35 -> 0.3 | J37: =IF(ABS(H37-$B$6)>$B$7,1,0) -> 0 | K37: =IF(ABS(I37-$C$6)>$C$7,1,0) -> 0 | L37: =J37*K37 -> 0 | M37: =IF(L37=1,H37,"") | N37: =IF(L37=1,I37,"")
A38: Days in the subset (both at the same time) | B38: =SUM(L5:L525) -> 96 | D38: days | G38: =Sheet1!A36 -> 45614 | H38: =Sheet1!D36 -> -2.4 | I38: =Sheet1!E36 -> -2.5 | J38: =IF(ABS(H38-$B$6)>$B$7,1,0) -> 0 | K38: =IF(ABS(I38-$C$6)>$C$7,1,0) -> 0 | L38: =J38*K38 -> 0 | M38: =IF(L38=1,H38,"") | N38: =IF(L38=1,I38,"")
A39: Correlation on the subset | B39: =CORREL(M5:M525,N5:N525) -> 0.94590478 | D39: no units | G39: =Sheet1!A37 -> 45615 | H39: =Sheet1!D37 -> 0.1 | I39: =Sheet1!E37 -> -1.8 | J39: =IF(ABS(H39-$B$6)>$B$7,1,0) -> 0 | K39: =IF(ABS(I39-$C$6)>$C$7,1,0) -> 0 | L39: =J39*K39 -> 0 | M39: =IF(L39=1,H39,"") | N39: =IF(L39=1,I39,"")
A40: Subset days with both yields up | B40: =COUNTIFS(M5:M525,">0",N5:N525,">0") -> 44 | D40: days | G40: =Sheet1!A38 -> 45616 | H40: =Sheet1!D38 -> 3.5 | I40: =Sheet1!E38 -> 1.5 | J40: =IF(ABS(H40-$B$6)>$B$7,1,0) -> 0 | K40: =IF(ABS(I40-$C$6)>$C$7,1,0) -> 0 | L40: =J40*K40 -> 0 | M40: =IF(L40=1,H40,"") | N40: =IF(L40=1,I40,"")
...

Sheet Q5-Q7 VaR
A1: Q5 to Q7: PV01 hedge, equal-PV01 portfolio and 99% 1-day VaR
A2: Blue numbers are typed inputs. Everything else is a formula. | G2: Price chg (% of par) = -PV01 x chg/100 + 0.5 x d2P/dY2 x chg^2/10000. P&L ($) = face x price chg / 100.
A3: Bond inputs (from the Bloomberg screens on Sheet1) | B3: 2-yr Tsy | C3: 10-yr Tsy | D3: Units | G3: Daily repricing: every historical day applied to today's position
A4: PV01 = -dP/dY | B4: =Sheet1!I18 -> 1.878 | C4: =Sheet1!J42 -> 7.382 | D4: price points per 100 face, per 100 bp | G4: Date | H4: 2-yr chg (bp) | I4: 10-yr chg (bp) | J4: 2-yr price chg (% of par) | K4: 10-yr price chg (% of par) | L4: 2-yr leg P&L ($) | M4: 10-yr leg P&L ($) | N4: Portfolio P&L ($) | O4: Portfolio P&L, 1st order only ($)
A5: d2P/dY2 | B5: =Sheet1!I19 -> 0.044888085 | C5: =Sheet1!J43 -> 0.69078167 | D5: price points per 100 face, per (100 bp)^2 | G5: =Sheet1!A3 -> 45567 | H5: =Sheet1!D3 -> 3.7 | I5: =Sheet1!E3 -> 5.1 | J5: =-$B$4*H5/100+0.5*$B$5*H5^2/10000 -> -0.069455274 | K5: =-$C$4*I5/100+0.5*$C$5*I5^2/10000 -> -0.37558364 | L5: =$B$17*1000000*J5/100 -> -10418.291 | M5: =$B$19*1000000*K5/100 -> -14332.418 | N5: =L5+M5 -> -24750.709 | O5: =-($B$18*H5+$B$20*I5) -> -24789.6
A6: DV01 per $1 million face | B6: =B4/100*1000000/100 -> 187.8 | C6: =C4/100*1000000/100 -> 738.2 | D6: $ per bp | G6: =Sheet1!A4 -> 45568 | H6: =Sheet1!D4 -> 6.3 | I6: =Sheet1!E4 -> 6.4 | J6: =-$B$4*H6/100+0.5*$B$5*H6^2/10000 -> -0.11822492 | K6: =-$C$4*I6/100+0.5*$C$5*I6^2/10000 -> -0.47103328 | L6: =$B$17*1000000*J6/100 -> -17733.738 | M6: =$B$19*1000000*K6/100 -> -17974.814 | N6: =L6+M6 -> -35708.552 | O6: =-($B$18*H6+$B$20*I6) -> -35775.9
G7: =Sheet1!A5 -> 45569 | H7: =Sheet1!D5 -> 21.8 | I7: =Sheet1!E5 -> 12.1 | J7: =-$B$4*H7/100+0.5*$B$5*H7^2/10000 -> -0.40833737 | K7: =-$C$4*I7/100+0.5*$C$5*I7^2/10000 -> -0.88816513 | L7: =$B$17*1000000*J7/100 -> -61250.605 | M7: =$B$19*1000000*K7/100 -> -33892.728 | N7: =L7+M7 -> -95143.333 | O7: =-($B$18*H7+$B$20*I7) -> -95496.3
A8: Q5. Long $20 million 10-yr notes: 2-yr notes to sell for zero PV01 | B8: Value | D8: Units | G8: =Sheet1!A6 -> 45572 | H8: =Sheet1!D6 -> 7.2 | I8: =Sheet1!E6 -> 5.9 | J8: =-$B$4*H8/100+0.5*$B$5*H8^2/10000 -> -0.13509965 | K8: =-$C$4*I8/100+0.5*$C$5*I8^2/10000 -> -0.43433569 | L8: =$B$17*1000000*J8/100 -> -20264.948 | M8: =$B$19*1000000*K8/100 -> -16574.42 | N8: =L8+M8 -> -36839.367 | O8: =-($B$18*H8+$B$20*I8) -> -36902.7
A9: Long 10-yr position | B9: 20 | D9: $ million face | G9: =Sheet1!A7 -> 45573 | H9: =Sheet1!D7 -> -3.7 | I9: =Sheet1!E7 -> -1.4 | J9: =-$B$4*H9/100+0.5*$B$5*H9^2/10000 -> 0.069516726 | K9: =-$C$4*I9/100+0.5*$C$5*I9^2/10000 -> 0.1034157 | L9: =$B$17*1000000*J9/100 -> 10427.509 | M9: =$B$19*1000000*K9/100 -> 3946.3833 | N9: =L9+M9 -> 14373.892 | O9: =-($B$18*H9+$B$20*I9) -> 14366.7
A10: DV01 of the long 10-yr position | B10: =B9*C6 -> 14764 | D10: $ per bp | G10: =Sheet1!A8 -> 45574 | H10: =Sheet1!D8 -> 6.5 | I10: =Sheet1!E8 -> 6.1 | J10: =-$B$4*H10/100+0.5*$B$5*H10^2/10000 -> -0.12197517 | K10: =-$C$4*I10/100+0.5*$C$5*I10^2/10000 -> -0.4490168 | L10: =$B$17*1000000*J10/100 -> -18296.276 | M10: =$B$19*1000000*K10/100 -> -17134.656 | N10: =L10+M10 -> -35430.932 | O10: =-($B$18*H10+$B$20*I10) -> -35494.2
A11: 2-yr notes to sell | B11: =B9*C4/B4 -> 78.615548 | D11: $ million face | G11: =Sheet1!A9 -> 45575 | H11: =Sheet1!D9 -> -6.5 | I11: =Sheet1!E9 -> -1.1 | J11: =-$B$4*H11/100+0.5*$B$5*H11^2/10000 -> 0.12216483 | K11: =-$C$4*I11/100+0.5*$C$5*I11^2/10000 -> 0.081243792 | L11: =$B$17*1000000*J11/100 -> 18324.724 | M11: =$B$19*1000000*K11/100 -> 3100.2948 | N11: =L11+M11 -> 21425.019 | O11: =-($B$18*H11+$B$20*I11) -> 21409.2
A12: DV01 of the short 2-yr position | B12: =-B11*B6 -> -14764 | D12: $ per bp | G12: =Sheet1!A10 -> 45576 | H12: =Sheet1!D10 -> -0.2 | I12: =Sheet1!E10 -> 3.8 | J12: =-$B$4*H12/100+0.5*$B$5*H12^2/10000 -> 0.0037560898 | K12: =-$C$4*I12/100+0.5*$C$5*I12^2/10000 -> -0.28001726 | L12: =$B$17*1000000*J12/100 -> 563.41347 | M12: =$B$19*1000000*K12/100 -> -10685.568 | N12: =L12+M12 -> -10122.154 | O12: =-($B$18*H12+$B$20*I12) -> -10141.2
A13: Net DV01 after the hedge | B13: =B10+B12 -> 0 | D13: $ per bp | G13: =Sheet1!A11 -> 45579 | H13: =Sheet1!D11 -> 0 | I13: =Sheet1!E11 -> 0 | J13: =-$B$4*H13/100+0.5*$B$5*H13^2/10000 -> 0 | K13: =-$C$4*I13/100+0.5*$C$5*I13^2/10000 -> 0 | L13: =$B$17*1000000*J13/100 -> 0 | M13: =$B$19*1000000*K13/100 -> 0 | N13: =L13+M13 -> 0 | O13: =-($B$18*H13+$B$20*I13) -> 0
A14: Hedge ratio (2-yr face per 1 of 10-yr face) | B14: =C4/B4 -> 3.9307774 | D14: x | G14: =Sheet1!A12 -> 45580 | H14: =Sheet1!D12 -> -0.9 | I14: =Sheet1!E12 -> -6.7 | J14: =-$B$4*H14/100+0.5*$B$5*H14^2/10000 -> 0.016903818 | K14: =-$C$4*I14/100+0.5*$C$5*I14^2/10000 -> 0.49614446 | L14: =$B$17*1000000*J14/100 -> 2535.5727 | M14: =$B$19*1000000*K14/100 -> 18933.066 | N14: =L14+M14 -> 21468.639 | O14: =-($B$18*H14+$B$20*I14) -> 21409.2
G15: =Sheet1!A13 -> 45581 | H15: =Sheet1!D13 -> -0.8 | I15: =Sheet1!E13 -> -2 | J15: =-$B$4*H15/100+0.5*$B$5*H15^2/10000 -> 0.015025436 | K15: =-$C$4*I15/100+0.5*$C$5*I15^2/10000 -> 0.14777816 | L15: =$B$17*1000000*J15/100 -> 2253.8155 | M15: =$B$19*1000000*K15/100 -> 5639.2721 | N15: =L15+M15 -> 7893.0876 | O15: =-($B$18*H15+$B$20*I15) -> 7887.6
A16: Q6. Long $15 million 2-yr notes plus 10-yr notes with the same PV01 | B16: Value | D16: Units | G16: =Sheet1!A14 -> 45582 | H16: =Sheet1!D14 -> 3.3 | I16: =Sheet1!E14 -> 7.8 | J16: =-$B$4*H16/100+0.5*$B$5*H16^2/10000 -> -0.061949558 | K16: =-$C$4*I16/100+0.5*$C$5*I16^2/10000 -> -0.57369464 | L16: =$B$17*1000000*J16/100 -> -9292.4338 | M16: =$B$19*1000000*K16/100 -> -21892.411 | N16: =L16+M16 -> -31184.845 | O16: =-($B$18*H16+$B$20*I16) -> -31268.7
A17: Long 2-yr position | B17: 15 | D17: $ million face | G17: =Sheet1!A15 -> 45583 | H17: =Sheet1!D15 -> -2.4 | I17: =Sheet1!E15 -> -0.8 | J17: =-$B$4*H17/100+0.5*$B$5*H17^2/10000 -> 0.045084928 | K17: =-$C$4*I17/100+0.5*$C$5*I17^2/10000 -> 0.059078105 | L17: =$B$17*1000000*J17/100 -> 6762.7392 | M17: =$B$19*1000000*K17/100 -> 2254.4435 | N17: =L17+M17 -> 9017.1827 | O17: =-($B$18*H17+$B$20*I17) -> 9014.4
A18: DV01 of the 2-yr leg | B18: =B17*B6 -> 2817 | D18: $ per bp | G18: =Sheet1!A16 -> 45586 | H18: =Sheet1!D16 -> 8.4 | I18: =Sheet1!E16 -> 11.3 | J18: =-$B$4*H18/100+0.5*$B$5*H18^2/10000 -> -0.15759363 | K18: =-$C$4*I18/100+0.5*$C$5*I18^2/10000 -> -0.8297557 | L18: =$B$17*1000000*J18/100 -> -23639.045 | M18: =$B$19*1000000*K18/100 -> -31663.801 | N18: =L18+M18 -> -55302.847 | O18: =-($B$18*H18+$B$20*I18) -> -55494.9
A19: 10-yr notes needed for the same PV01 | B19: =B17*B4/C4 -> 3.816039 | D19: $ million face | G19: =Sheet1!A17 -> 45587 | H19: =Sheet1!D17 -> 0 | I19: =Sheet1!E17 -> 1.2 | J19: =-$B$4*H19/100+0.5*$B$5*H19^2/10000 -> 0 | K19: =-$C$4*I19/100+0.5*$C$5*I19^2/10000 -> -0.088534264 | L19: =$B$17*1000000*J19/100 -> 0 | M19: =$B$19*1000000*K19/100 -> -3378.502 | N19: =L19+M19 -> -3378.502 | O19: =-($B$18*H19+$B$20*I19) -> -3380.4
A20: DV01 of the 10-yr leg | B20: =B19*C6 -> 2817 | D20: $ per bp | G20: =Sheet1!A18 -> 45588 | H20: =Sheet1!D18 -> 4.7 | I20: =Sheet1!E18 -> 3.8 | J20: =-$B$4*H20/100+0.5*$B$5*H20^2/10000 -> -0.088216421 | K20: =-$C$4*I20/100+0.5*$C$5*I20^2/10000 -> -0.28001726 | L20: =$B$17*1000000*J20/100 -> -13232.463 | M20: =$B$19*1000000*K20/100 -> -10685.568 | N20: =L20+M20 -> -23918.031 | O20: =-($B$18*H20+$B$20*I20) -> -23944.5
A21: Total DV01 of the portfolio | B21: =B18+B20 -> 5634 | D21: $ per bp | G21: =Sheet1!A19 -> 45589 | H21: =Sheet1!D19 -> 0.1 | I21: =Sheet1!E19 -> -3.4 | J21: =-$B$4*H21/100+0.5*$B$5*H21^2/10000 -> -0.0018779776 | K21: =-$C$4*I21/100+0.5*$C$5*I21^2/10000 -> 0.25138727 | L21: =$B$17*1000000*J21/100 -> -281.69663 | M21: =$B$19*1000000*K21/100 -> 9593.0364 | N21: =L21+M21 -> 9311.3397 | O21: =-($B$18*H21+$B$20*I21) -> 9296.1
G22: =Sheet1!A20 -> 45590 | H22: =Sheet1!D20 -> 2.6 | I22: =Sheet1!E20 -> 2.8 | J22: =-$B$4*H22/100+0.5*$B$5*H22^2/10000 -> -0.048812828 | K22: =-$C$4*I22/100+0.5*$C$5*I22^2/10000 -> -0.20642521 | L22: =$B$17*1000000*J22/100 -> -7321.9242 | M22: =$B$19*1000000*K22/100 -> -7877.2667 | N22: =L22+M22 -> -15199.191 | O22: =-($B$18*H22+$B$20*I22) -> -15211.8
A23: Same PV01, same risk? Each leg on its own | B23: 2-yr leg | C23: 10-yr leg | D23: Units | G23: =Sheet1!A21 -> 45593 | H23: =Sheet1!D21 -> 3.4 | I23: =Sheet1!E21 -> 4.2 | J23: =-$B$4*H23/100+0.5*$B$5*H23^2/10000 -> -0.063826055 | K23: =-$C$4*I23/100+0.5*$C$5*I23^2/10000 -> -0.30943473 | L23: =$B$17*1000000*J23/100 -> -9573.9082 | M23: =$B$19*1000000*K23/100 -> -11808.15 | N23: =L23+M23 -> -21382.058 | O23: =-($B$18*H23+$B$20*I23) -> -21409.2
A24: Daily SD of the yield change | B24: ='Q1-Q4 Stats'!B7 -> 4.8802576 | C24: ='Q1-Q4 Stats'!C7 -> 4.8538523 | D24: bp | G24: =Sheet1!A22 -> 45594 | H24: =Sheet1!D22 -> -4.3 | I24: =Sheet1!E22 -> -2.8 | J24: =-$B$4*H24/100+0.5*$B$5*H24^2/10000 -> 0.080795499 | K24: =-$C$4*I24/100+0.5*$C$5*I24^2/10000 -> 0.20696679 | L24: =$B$17*1000000*J24/100 -> 12119.325 | M24: =$B$19*1000000*K24/100 -> 7897.9333 | N24: =L24+M24 -> 20017.258 | O24: =-($B$18*H24+$B$20*I24) -> 20000.7
A25: Excess kurtosis of the yield change | B25: ='Q1-Q4 Stats'!B8 -> 2.8837219 | C25: ='Q1-Q4 Stats'!C8 -> 0.67159117 | D25: no units | G25: =Sheet1!A23 -> 45595 | H25: =Sheet1!D23 -> 8.6 | I25: =Sheet1!E23 -> 4.6 | J25: =-$B$4*H25/100+0.5*$B$5*H25^2/10000 -> -0.161342 | K25: =-$C$4*I25/100+0.5*$C$5*I25^2/10000 -> -0.33884115 | L25: =$B$17*1000000*J25/100 -> -24201.301 | M25: =$B$19*1000000*K25/100 -> -12930.311 | N25: =L25+M25 -> -37131.611 | O25: =-($B$18*H25+$B$20*I25) -> -37184.4
A26: Daily SD of the leg P&L | B26: =_xlfn.STDEV.S(L5:L525) -> 13746.696 | C26: =_xlfn.STDEV.S(M5:M525) -> 13666.774 | D26: $ | G26: =Sheet1!A24 -> 45596 | H26: =Sheet1!D24 -> -1.2 | I26: =Sheet1!E24 -> -1.6 | J26: =-$B$4*H26/100+0.5*$B$5*H26^2/10000 -> 0.022539232 | K26: =-$C$4*I26/100+0.5*$C$5*I26^2/10000 -> 0.11820042 | L26: =$B$17*1000000*J26/100 -> 3380.8848 | M26: =$B$19*1000000*K26/100 -> 4510.5741 | N26: =L26+M26 -> 7891.4589 | O26: =-($B$18*H26+$B$20*I26) -> 7887.6
A27: Stand-alone 99% 1-day VaR | B27: =-_xlfn.PERCENTILE.INC(L5:L525,1-$B$32) -> 34654.332 | C27: =-_xlfn.PERCENTILE.INC(M5:M525,1-$B$32) -> 34115.526 | D27: $ | G27: =Sheet1!A25 -> 45597 | H27: =Sheet1!D25 -> 3.7 | I27: =Sheet1!E25 -> 10 | J27: =-$B$4*H27/100+0.5*$B$5*H27^2/10000 -> -0.069455274 | K27: =-$C$4*I27/100+0.5*$C$5*I27^2/10000 -> -0.73474609 | L27: =$B$17*1000000*J27/100 -> -10418.291 | M27: =$B$19*1000000*K27/100 -> -28038.198 | N27: =L27+M27 -> -38456.489 | O27: =-($B$18*H27+$B$20*I27) -> -38592.9
A28: Worst 1-day loss in the window | B28: =-MIN(L5:L525) -> 61250.605 | C28: =-MIN(M5:M525) -> 52770.488 | D28: $ | G28: =Sheet1!A26 -> 45600 | H28: =Sheet1!D26 -> -4.7 | I28: =Sheet1!E26 -> -9.9 | J28: =-$B$4*H28/100+0.5*$B$5*H28^2/10000 -> 0.088315579 | K28: =-$C$4*I28/100+0.5*$C$5*I28^2/10000 -> 0.73420318 | L28: =$B$17*1000000*J28/100 -> 13247.337 | M28: =$B$19*1000000*K28/100 -> 28017.48 | N28: =L28+M28 -> 41264.816 | O28: =-($B$18*H28+$B$20*I28) -> 41128.2
A29: Share of portfolio P&L variance | B29: =_xlfn.COVARIANCE.S(L5:L525,N5:N525)/_xlfn.VAR.S(N5:N525) -> 0.50160129 | C29: =_xlfn.COVARIANCE.S(M5:M525,N5:N525)/_xlfn.VAR.S(N5:N525) -> 0.49839871 | D29: % of variance | G29: =Sheet1!A27 -> 45601 | H29: =Sheet1!D27 -> 1.8 | I29: =Sheet1!E27 -> -1.3 | J29: =-$B$4*H29/100+0.5*$B$5*H29^2/10000 -> -0.033796728 | K29: =-$C$4*I29/100+0.5*$C$5*I29^2/10000 -> 0.096024371 | L29: =$B$17*1000000*J29/100 -> -5069.5092 | M29: =$B$19*1000000*K29/100 -> 3664.3275 | N29: =L29+M29 -> -1405.1818 | O29: =-($B$18*H29+$B$20*I29) -> -1408.5
G30: =Sheet1!A28 -> 45602 | H30: =Sheet1!D28 -> 8.4 | I30: =Sheet1!E28 -> 16 | J30: =-$B$4*H30/100+0.5*$B$5*H30^2/10000 -> -0.15759363 | K30: =-$C$4*I30/100+0.5*$C$5*I30^2/10000 -> -1.172278 | L30: =$B$17*1000000*J30/100 -> -23639.045 | M30: =$B$19*1000000*K30/100 -> -44734.586 | N30: =L30+M30 -> -68373.631 | O30: =-($B$18*H30+$B$20*I30) -> -68734.8
A31: Q7. 99% 1-day VaR of the Q6 portfolio (historical simulation) | B31: Value | D31: Units | G31: =Sheet1!A29 -> 45603 | H31: =Sheet1!D29 -> -6.4 | I31: =Sheet1!E29 -> -10.5 | J31: =-$B$4*H31/100+0.5*$B$5*H31^2/10000 -> 0.12028393 | K31: =-$C$4*I31/100+0.5*$C$5*I31^2/10000 -> 0.77891793 | L31: =$B$17*1000000*J31/100 -> 18042.59 | M31: =$B$19*1000000*K31/100 -> 29723.812 | N31: =L31+M31 -> 47766.402 | O31: =-($B$18*H31+$B$20*I31) -> 47607.3
A32: Confidence level | B32: 0.99 | D32: probability | G32: =Sheet1!A30 -> 45604 | H32: =Sheet1!D30 -> 5.5 | I32: =Sheet1!E30 -> -2.3 | J32: =-$B$4*H32/100+0.5*$B$5*H32^2/10000 -> -0.10322211 | K32: =-$C$4*I32/100+0.5*$C$5*I32^2/10000 -> 0.16996871 | L32: =$B$17*1000000*J32/100 -> -15483.316 | M32: =$B$19*1000000*K32/100 -> 6486.0724 | N32: =L32+M32 -> -8997.2437 | O32: =-($B$18*H32+$B$20*I32) -> -9014.4
A33: Number of historical scenarios | B33: =COUNT(N5:N525) -> 521 | D33: days | G33: =Sheet1!A31 -> 45607 | H33: =Sheet1!D31 -> 0 | I33: =Sheet1!E31 -> 0 | J33: =-$B$4*H33/100+0.5*$B$5*H33^2/10000 -> 0 | K33: =-$C$4*I33/100+0.5*$C$5*I33^2/10000 -> 0 | L33: =$B$17*1000000*J33/100 -> 0 | M33: =$B$19*1000000*K33/100 -> 0 | N33: =L33+M33 -> 0 | O33: =-($B$18*H33+$B$20*I33) -> 0
A34: 99% 1-day VaR = -(1st percentile of P&L) | B34: =-_xlfn.PERCENTILE.INC(N5:N525,1-B32) -> 66844.07 | D34: $ | G34: =Sheet1!A32 -> 45608 | H34: =Sheet1!D32 -> 8.7 | I34: =Sheet1!E32 -> 12.4 | J34: =-$B$4*H34/100+0.5*$B$5*H34^2/10000 -> -0.16321612 | K34: =-$C$4*I34/100+0.5*$C$5*I34^2/10000 -> -0.91005727 | L34: =$B$17*1000000*J34/100 -> -24482.418 | M34: =$B$19*1000000*K34/100 -> -34728.14 | N34: =L34+M34 -> -59210.559 | O34: =-($B$18*H34+$B$20*I34) -> -59438.7
A35: 5th worst daily loss | B35: =-SMALL(N5:N525,5) -> 68373.631 | D35: $ | G35: =Sheet1!A33 -> 45609 | H35: =Sheet1!D33 -> -5.4 | I35: =Sheet1!E33 -> 2.3 | J35: =-$B$4*H35/100+0.5*$B$5*H35^2/10000 -> 0.10147745 | K35: =-$C$4*I35/100+0.5*$C$5*I35^2/10000 -> -0.16960329 | L35: =$B$17*1000000*J35/100 -> 15221.617 | M35: =$B$19*1000000*K35/100 -> -6472.1276 | N35: =L35+M35 -> 8749.4894 | O35: =-($B$18*H35+$B$20*I35) -> 8732.7
A36: 6th worst daily loss | B36: =-SMALL(N5:N525,6) -> 67341.815 | D36: $ | G36: =Sheet1!A34 -> 45610 | H36: =Sheet1!D34 -> 5.9 | I36: =Sheet1!E34 -> -1.5 | J36: =-$B$4*H36/100+0.5*$B$5*H36^2/10000 -> -0.11072387 | K36: =-$C$4*I36/100+0.5*$C$5*I36^2/10000 -> 0.11080771 | L36: =$B$17*1000000*J36/100 -> -16608.581 | M36: =$B$19*1000000*K36/100 -> 4228.4656 | N36: =L36+M36 -> -12380.115 | O36: =-($B$18*H36+$B$20*I36) -> -12394.8
A37: Worst daily loss in the window | B37: =-MIN(N5:N525) -> 95143.333 | D37: $ | G37: =Sheet1!A35 -> 45611 | H37: =Sheet1!D35 -> -4.2 | I37: =Sheet1!E35 -> 0.3 | J37: =-$B$4*H37/100+0.5*$B$5*H37^2/10000 -> 0.078915591 | K37: =-$C$4*I37/100+0.5*$C$5*I37^2/10000 -> -0.022142891 | L37: =$B$17*1000000*J37/100 -> 11837.339 | M37: =$B$19*1000000*K37/100 -> -844.98138 | N37: =L37+M37 -> 10992.357 | O37: =-($B$18*H37+$B$20*I37) -> 10986.3
A38: Mean daily P&L | B38: =AVERAGE(N5:N525) -> -1495.3474 | D38: $ | G38: =Sheet1!A36 -> 45614 | H38: =Sheet1!D36 -> -2.4 | I38: =Sheet1!E36 -> -2.5 | J38: =-$B$4*H38/100+0.5*$B$5*H38^2/10000 -> 0.045084928 | K38: =-$C$4*I38/100+0.5*$C$5*I38^2/10000 -> 0.18476587 | L38: =$B$17*1000000*J38/100 -> 6762.7392 | M38: =$B$19*1000000*K38/100 -> 7050.7377 | N38: =L38+M38 -> 13813.477 | O38: =-($B$18*H38+$B$20*I38) -> 13803.3
A39: SD of daily P&L | B39: =_xlfn.STDEV.S(N5:N525) -> 26155.64 | D39: $ | G39: =Sheet1!A37 -> 45615 | H39: =Sheet1!D37 -> 0.1 | I39: =Sheet1!E37 -> -1.8 | J39: =-$B$4*H39/100+0.5*$B$5*H39^2/10000 -> -0.0018779776 | K39: =-$C$4*I39/100+0.5*$C$5*I39^2/10000 -> 0.13298791 | L39: =$B$17*1000000*J39/100 -> -281.69663 | M39: =$B$19*1000000*K39/100 -> 5074.8704 | N39: =L39+M39 -> 4793.1738 | O39: =-($B$18*H39+$B$20*I39) -> 4788.9
A40: Check: normal VaR = 2.326 x SD | B40: =_xlfn.NORM.S.INV(B32)*B39 -> 60847.119 | D40: $ | G40: =Sheet1!A38 -> 45616 | H40: =Sheet1!D38 -> 3.5 | I40: =Sheet1!E38 -> 1.5 | J40: =-$B$4*H40/100+0.5*$B$5*H40^2/10000 -> -0.065702506 | K40: =-$C$4*I40/100+0.5*$C$5*I40^2/10000 -> -0.11065229 | L40: =$B$17*1000000*J40/100 -> -9855.3759 | M40: =$B$19*1000000*K40/100 -> -4222.5344 | N40: =L40+M40 -> -14077.91 | O40: =-($B$18*H40+$B$20*I40) -> -14085
...

Sheet Q8 VaR Graph
A1: Q8: 99% 1-day VaR of P(A) = $15 million 2-yr notes + A million 10-yr notes
A2: A < 0 means the 10-yr notes are sold short. Same historical simulation and repricing as Q7.
A4: Key points on the curve | B4: A ($ million face) | C4: 99% 1-day VaR ($) | D4: Net DV01 ($ per bp)
A5: Lowest VaR on the grid | B5: =INDEX($D$26:$CF$26,MATCH(MIN($D$28:$CF$28),$D$28:$CF$28,0)) -> -2.75 | C5: =MIN($D$28:$CF$28) -> 19532.975 | D5: =INDEX($D$27:$CF$27,MATCH(MIN($D$28:$CF$28),$D$28:$CF$28,0)) -> 786.95
A6: Zero total PV01 | B6: =-'Q5-Q7 VaR'!B19 -> -3.816039 | C6: =CG28 -> 20106.049 | D6: =CG27 -> 0
A7: Minimum-variance hedge (beta x zero-PV01 amount) | B7: =B6*B10 -> -3.1478545 | C7: =CH28 -> 19945.254 | D7: =CH27 -> 493.2538
A8: No 10-yr position (A = 0) | B8: 0 | C8: =INDEX($D$28:$CF$28,MATCH(0,$D$26:$CF$26,0)) -> 34654.332 | D8: =INDEX($D$27:$CF$27,MATCH(0,$D$26:$CF$26,0)) -> 2817
A9: Other inputs | B9: Value | D9: Units
A10: Beta of 2-yr change on 10-yr change (regression slope) | B10: =SLOPE(Sheet1!$D$3:$D$523,Sheet1!$E$3:$E$523) -> 0.82490103 | D10: bp per bp
A11: Grid start for A | B11: -10 | D11: $ million face
A12: Grid step for A | B12: 0.25 | D12: $ million face
A13: Risk left after the best linear hedge = sqrt(1 - corr^2) | B13: =SQRT(1-'Q1-Q4 Stats'!B23^2) -> 0.57173579 | D13: % of unhedged SD
A14: Lowest VaR as a share of the VaR with no hedge | B14: =C5/C8 -> 0.56365175 | D14: % of unhedged VaR
A16: Vertical marker lines for the chart | B16: A ($ million face) | C16: VaR ($)
A17: Lowest VaR: bottom of line | B17: =B5 -> -2.75 | C17: 0
A18: Lowest VaR: top of line | B18: =B5 -> -2.75 | C18: =C5 -> 19532.975
A19: Zero total PV01: bottom of line | B19: =B6 -> -3.816039 | C19: 0
A20: Zero total PV01: top of line | B20: =B6 -> -3.816039 | C20: =C6 -> 20106.049
A25: P&L grid: each column is the portfolio P&L for one value of A = 2-yr leg P&L + A x (10-yr P&L per $1 million). | CG25: Zero PV01 | CH25: Min variance
A26: A ($ million face of 10-yr notes) | D26: =$B$11 -> -10 | E26: =D26+$B$12 -> -9.75 | F26: =E26+$B$12 -> -9.5 | G26: =F26+$B$12 -> -9.25 | H26: =G26+$B$12 -> -9 | I26: =H26+$B$12 -> -8.75 | J26: =I26+$B$12 -> -8.5 | K26: =J26+$B$12 -> -8.25 | L26: =K26+$B$12 -> -8 | ... CF26: =CE26+$B$12 -> 10 | CG26: =$B$6 -> -3.816039 | CH26: =$B$7 -> -3.1478545
A27: Net DV01 ($ per bp) | D27: ='Q5-Q7 VaR'!$B$18+D26*'Q5-Q7 VaR'!$C$6 -> -4565 | E27: ='Q5-Q7 VaR'!$B$18+E26*'Q5-Q7 VaR'!$C$6 -> -4380.45 | F27: ='Q5-Q7 VaR'!$B$18+F26*'Q5-Q7 VaR'!$C$6 -> -4195.9 | G27: ='Q5-Q7 VaR'!$B$18+G26*'Q5-Q7 VaR'!$C$6 -> -4011.35 | H27: ='Q5-Q7 VaR'!$B$18+H26*'Q5-Q7 VaR'!$C$6 -> -3826.8 | I27: ='Q5-Q7 VaR'!$B$18+I26*'Q5-Q7 VaR'!$C$6 -> -3642.25 | J27: ='Q5-Q7 VaR'!$B$18+J26*'Q5-Q7 VaR'!$C$6 -> -3457.7 | K27: ='Q5-Q7 VaR'!$B$18+K26*'Q5-Q7 VaR'!$C$6 -> -3273.15 | ... CH27: ='Q5-Q7 VaR'!$B$18+CH26*'Q5-Q7 VaR'!$C$6 -> 493.2538
A28: 99% 1-day VaR ($) | D28: =-_xlfn.PERCENTILE.INC(D31:D551,1-'Q5-Q7 VaR'!$B$32) -> 59841.005 | E28: =-_xlfn.PERCENTILE.INC(E31:E551,1-'Q5-Q7 VaR'!$B$32) -> 57871.34 | F28: =-_xlfn.PERCENTILE.INC(F31:F551,1-'Q5-Q7 VaR'!$B$32) -> 55901.676 | G28: =-_xlfn.PERCENTILE.INC(G31:G551,1-'Q5-Q7 VaR'!$B$32) -> 53932.011 | H28: =-_xlfn.PERCENTILE.INC(H31:H551,1-'Q5-Q7 VaR'!$B$32) -> 51962.346 | I28: =-_xlfn.PERCENTILE.INC(I31:I551,1-'Q5-Q7 VaR'!$B$32) -> 49992.682 | J28: =-_xlfn.PERCENTILE.INC(J31:J551,1-'Q5-Q7 VaR'!$B$32) -> 48023.017 | K28: =-_xlfn.PERCENTILE.INC(K31:K551,1-'Q5-Q7 VaR'!$B$32) -> 46053.352 | ... CH28: =-_xlfn.PERCENTILE.INC(CH31:CH551,1-'Q5-Q7 VaR'!$B$32) -> 19945.254
A30: Date | B30: 2-yr leg P&L ($) | C30: 10-yr P&L per $1 million face ($) | D30: Portfolio P&L ($) for each A, across
A31: ='Q5-Q7 VaR'!G5 -> 45567 | B31: ='Q5-Q7 VaR'!L5 -> -10418.291 | C31: =1000000*'Q5-Q7 VaR'!K5/100 -> -3755.8364 | D31: =$B31+D$26*$C31 -> 27140.073 | E31: =$B31+E$26*$C31 -> 26201.114 | F31: =$B31+F$26*$C31 -> 25262.155 | G31: =$B31+G$26*$C31 -> 24323.195 | H31: =$B31+H$26*$C31 -> 23384.236 | I31: =$B31+I$26*$C31 -> 22445.277 | J31: =$B31+J$26*$C31 -> 21506.318 | K31: =$B31+K$26*$C31 -> 20567.359 | ... CH31: =$B31+CH$26*$C31 -> 1404.5354
A32: ='Q5-Q7 VaR'!G6 -> 45568 | B32: ='Q5-Q7 VaR'!L6 -> -17733.738 | C32: =1000000*'Q5-Q7 VaR'!K6/100 -> -4710.3328 | D32: =$B32+D$26*$C32 -> 29369.59 | E32: =$B32+E$26*$C32 -> 28192.007 | F32: =$B32+F$26*$C32 -> 27014.424 | G32: =$B32+G$26*$C32 -> 25836.84 | H32: =$B32+H$26*$C32 -> 24659.257 | I32: =$B32+I$26*$C32 -> 23481.674 | J32: =$B32+J$26*$C32 -> 22304.091 | K32: =$B32+K$26*$C32 -> 21126.508 | ... CH32: =$B32+CH$26*$C32 -> -2906.2956
A33: ='Q5-Q7 VaR'!G7 -> 45569 | B33: ='Q5-Q7 VaR'!L7 -> -61250.605 | C33: =1000000*'Q5-Q7 VaR'!K7/100 -> -8881.6513 | D33: =$B33+D$26*$C33 -> 27565.908 | E33: =$B33+E$26*$C33 -> 25345.495 | F33: =$B33+F$26*$C33 -> 23125.082 | G33: =$B33+G$26*$C33 -> 20904.669 | H33: =$B33+H$26*$C33 -> 18684.257 | I33: =$B33+I$26*$C33 -> 16463.844 | J33: =$B33+J$26*$C33 -> 14243.431 | K33: =$B33+K$26*$C33 -> 12023.018 | ... CH33: =$B33+CH$26*$C33 -> -33292.459
A34: ='Q5-Q7 VaR'!G8 -> 45572 | B34: ='Q5-Q7 VaR'!L8 -> -20264.948 | C34: =1000000*'Q5-Q7 VaR'!K8/100 -> -4343.3569 | D34: =$B34+D$26*$C34 -> 23168.622 | E34: =$B34+E$26*$C34 -> 22082.783 | F34: =$B34+F$26*$C34 -> 20996.943 | G34: =$B34+G$26*$C34 -> 19911.104 | H34: =$B34+H$26*$C34 -> 18825.265 | I34: =$B34+I$26*$C34 -> 17739.426 | J34: =$B34+J$26*$C34 -> 16653.587 | K34: =$B34+K$26*$C34 -> 15567.747 | ... CH34: =$B34+CH$26*$C34 -> -6592.6917
A35: ='Q5-Q7 VaR'!G9 -> 45573 | B35: ='Q5-Q7 VaR'!L9 -> 10427.509 | C35: =1000000*'Q5-Q7 VaR'!K9/100 -> 1034.157 | D35: =$B35+D$26*$C35 -> 85.939224 | E35: =$B35+E$26*$C35 -> 344.47847 | F35: =$B35+F$26*$C35 -> 603.01771 | G35: =$B35+G$26*$C35 -> 861.55695 | H35: =$B35+H$26*$C35 -> 1120.0962 | I35: =$B35+I$26*$C35 -> 1378.6354 | J35: =$B35+J$26*$C35 -> 1637.1747 | K35: =$B35+K$26*$C35 -> 1895.7139 | ... CH35: =$B35+CH$26*$C35 -> 7172.1332
A36: ='Q5-Q7 VaR'!G10 -> 45574 | B36: ='Q5-Q7 VaR'!L10 -> -18296.276 | C36: =1000000*'Q5-Q7 VaR'!K10/100 -> -4490.168 | D36: =$B36+D$26*$C36 -> 26605.404 | E36: =$B36+E$26*$C36 -> 25482.862 | F36: =$B36+F$26*$C36 -> 24360.32 | G36: =$B36+G$26*$C36 -> 23237.778 | H36: =$B36+H$26*$C36 -> 22115.236 | I36: =$B36+I$26*$C36 -> 20992.694 | J36: =$B36+J$26*$C36 -> 19870.152 | K36: =$B36+K$26*$C36 -> 18747.61 | ... CH36: =$B36+CH$26*$C36 -> -4161.8804
A37: ='Q5-Q7 VaR'!G11 -> 45575 | B37: ='Q5-Q7 VaR'!L11 -> 18324.724 | C37: =1000000*'Q5-Q7 VaR'!K11/100 -> 812.43792 | D37: =$B37+D$26*$C37 -> 10200.345 | E37: =$B37+E$26*$C37 -> 10403.454 | F37: =$B37+F$26*$C37 -> 10606.564 | G37: =$B37+G$26*$C37 -> 10809.673 | H37: =$B37+H$26*$C37 -> 11012.783 | I37: =$B37+I$26*$C37 -> 11215.892 | J37: =$B37+J$26*$C37 -> 11419.002 | K37: =$B37+K$26*$C37 -> 11622.111 | ... CH37: =$B37+CH$26*$C37 -> 15767.288
A38: ='Q5-Q7 VaR'!G12 -> 45576 | B38: ='Q5-Q7 VaR'!L12 -> 563.41347 | C38: =1000000*'Q5-Q7 VaR'!K12/100 -> -2800.1726 | D38: =$B38+D$26*$C38 -> 28565.139 | E38: =$B38+E$26*$C38 -> 27865.096 | F38: =$B38+F$26*$C38 -> 27165.053 | G38: =$B38+G$26*$C38 -> 26465.01 | H38: =$B38+H$26*$C38 -> 25764.966 | I38: =$B38+I$26*$C38 -> 25064.923 | J38: =$B38+J$26*$C38 -> 24364.88 | K38: =$B38+K$26*$C38 -> 23664.837 | ... CH38: =$B38+CH$26*$C38 -> 9377.9493
A39: ='Q5-Q7 VaR'!G13 -> 45579 | B39: ='Q5-Q7 VaR'!L13 -> 0 | C39: =1000000*'Q5-Q7 VaR'!K13/100 -> 0 | D39: =$B39+D$26*$C39 -> 0 | E39: =$B39+E$26*$C39 -> 0 | F39: =$B39+F$26*$C39 -> 0 | G39: =$B39+G$26*$C39 -> 0 | H39: =$B39+H$26*$C39 -> 0 | I39: =$B39+I$26*$C39 -> 0 | J39: =$B39+J$26*$C39 -> 0 | K39: =$B39+K$26*$C39 -> 0 | ... CH39: =$B39+CH$26*$C39 -> 0
A40: ='Q5-Q7 VaR'!G14 -> 45580 | B40: ='Q5-Q7 VaR'!L14 -> 2535.5727 | C40: =1000000*'Q5-Q7 VaR'!K14/100 -> 4961.4446 | D40: =$B40+D$26*$C40 -> -47078.873 | E40: =$B40+E$26*$C40 -> -45838.512 | F40: =$B40+F$26*$C40 -> -44598.151 | G40: =$B40+G$26*$C40 -> -43357.79 | H40: =$B40+H$26*$C40 -> -42117.429 | I40: =$B40+I$26*$C40 -> -40877.068 | J40: =$B40+J$26*$C40 -> -39636.706 | K40: =$B40+K$26*$C40 -> -38396.345 | ... CH40: =$B40+CH$26*$C40 -> -13082.333
A41: ='Q5-Q7 VaR'!G15 -> 45581 | B41: ='Q5-Q7 VaR'!L15 -> 2253.8155 | C41: =1000000*'Q5-Q7 VaR'!K15/100 -> 1477.7816 | D41: =$B41+D$26*$C41 -> -12524 | E41: =$B41+E$26*$C41 -> -12154.555 | F41: =$B41+F$26*$C41 -> -11785.109 | G41: =$B41+G$26*$C41 -> -11415.664 | H41: =$B41+H$26*$C41 -> -11046.219 | I41: =$B41+I$26*$C41 -> -10676.773 | J41: =$B41+J$26*$C41 -> -10307.328 | K41: =$B41+K$26*$C41 -> -9937.8824 | ... CH41: =$B41+CH$26*$C41 -> -2398.0259
A42: ='Q5-Q7 VaR'!G16 -> 45582 | B42: ='Q5-Q7 VaR'!L16 -> -9292.4338 | C42: =1000000*'Q5-Q7 VaR'!K16/100 -> -5736.9464 | D42: =$B42+D$26*$C42 -> 48077.03 | E42: =$B42+E$26*$C42 -> 46642.794 | F42: =$B42+F$26*$C42 -> 45208.557 | G42: =$B42+G$26*$C42 -> 43774.321 | H42: =$B42+H$26*$C42 -> 42340.084 | I42: =$B42+I$26*$C42 -> 40905.847 | J42: =$B42+J$26*$C42 -> 39471.611 | K42: =$B42+K$26*$C42 -> 38037.374 | ... CH42: =$B42+CH$26*$C42 -> 8766.6389
... A551: ='Q5-Q7 VaR'!G525 -> 46295 | B551: ='Q5-Q7 VaR'!L525 -> -3098.2926 | C551: =1000000*'Q5-Q7 VaR'!K525/100 -> -3682.3652 | D551: =$B551+D$26*$C551 -> 33725.36 | E551: =$B551+E$26*$C551 -> 32804.768 | F551: =$B551+F$26*$C551 -> 31884.177 | G551: =$B551+G$26*$C551 -> 30963.586 | H551: =$B551+H$26*$C551 -> 30042.994 | I551: =$B551+I$26*$C551 -> 29122.403 | J551: =$B551+J$26*$C551 -> 28201.812 | K551: =$B551+K$26*$C551 -> 27281.22 | ... CH551: =$B551+CH$26*$C551 -> 8493.2574
